<?xml version="1.0" ?>
<robot name="URDF_DIRECCION_X" xmlns:xacro="http://www.ros.org/wiki/xacro">

<xacro:include filename="materials.xacro" />
<xacro:include filename="URDF_DIRECCION_X.trans" />
<xacro:include filename="URDF_DIRECCION_X.gazebo" />
<xacro:include filename="ros2_control.xacro" />

<link name="base_link">
  <inertial>
    <origin xyz="0.0015670288303076142 -0.04921817269007369 0.06681838893831736" rpy="0 0 0"/>
    <mass value="12.327465009702763"/>
    <inertia ixx="0.035971" iyy="0.036951" izz="0.063219" ixy="2.2e-05" iyz="1.1e-05" ixz="-0.000722"/>
  </inertial>
  <visual>
    <origin xyz="0 0 0" rpy="0 0 0"/>
    <geometry>
      <mesh filename="package://cloud_robot/urdf/meshes/base_link.stl" scale="0.001 0.001 0.001"/>
    </geometry>
    <material name="silver"/>
  </visual>
  <collision>
    <origin xyz="0 0 0" rpy="0 0 0"/>
    <geometry>
      <mesh filename="package://cloud_robot/urdf/meshes/base_link.stl" scale="0.001 0.001 0.001"/>
    </geometry>
  </collision>
</link>

<link name="Left_Front_Wheel_1">
  <inertial>
    <origin xyz="2.352961450818869e-07 0.03328000000000002 -5.551115123125783e-17" rpy="0 0 0"/>
    <mass value="3.8165954525863826"/>
    <inertia ixx="0.003628" iyy="0.004437" izz="0.003628" ixy="-0.0" iyz="-0.0" ixz="0.0"/>
  </inertial>
  <visual>
    <origin xyz="-0.080518 0.02156 -0.066" rpy="0 0 0"/>
    <geometry>
      <mesh filename="package://cloud_robot/urdf/meshes/Left_Front_Wheel_1.stl" scale="0.001 0.001 0.001"/>
    </geometry>
    <material name="silver"/>
  </visual>
  <collision>
    <origin xyz="-0.080518 0.02156 -0.066" rpy="0 0 0"/>
    <geometry>
      <mesh filename="package://cloud_robot/urdf/meshes/Left_Front_Wheel_1.stl" scale="0.001 0.001 0.001"/>
    </geometry>
  </collision>
</link>

<link name="Right_Front_Wheel_1">
  <inertial>
    <origin xyz="-9.514703854879292e-06 -0.03327999999999999 4.163336342344337e-17" rpy="0 0 0"/>
    <mass value="3.8165954525863826"/>
    <inertia ixx="0.003628" iyy="0.004437" izz="0.003628" ixy="0.0" iyz="-0.0" ixz="0.0"/>
  </inertial>
  <visual>
    <origin xyz="-0.080518 0.076826 -0.066" rpy="0 0 0"/>
    <geometry>
      <mesh filename="package://cloud_robot/urdf/meshes/Right_Front_Wheel_1.stl" scale="0.001 0.001 0.001"/>
    </geometry>
    <material name="silver"/>
  </visual>
  <collision>
    <origin xyz="-0.080518 0.076826 -0.066" rpy="0 0 0"/>
    <geometry>
      <mesh filename="package://cloud_robot/urdf/meshes/Right_Front_Wheel_1.stl" scale="0.001 0.001 0.001"/>
    </geometry>
  </collision>
</link>

<link name="Left_Rear_Wheel_1">
  <inertial>
    <origin xyz="-2.352961450818869e-07 0.033280000000000025 1.3877787807814457e-17" rpy="0 0 0"/>
    <mass value="3.8165954525863808"/>
    <inertia ixx="0.003628" iyy="0.004437" izz="0.003628" ixy="-0.0" iyz="0.0" ixz="-0.0"/>
  </inertial>
  <visual>
    <origin xyz="0.080518 0.02156 -0.066" rpy="0 0 0"/>
    <geometry>
      <mesh filename="package://cloud_robot/urdf/meshes/Left_Rear_Wheel_1.stl" scale="0.001 0.001 0.001"/>
    </geometry>
    <material name="silver"/>
  </visual>
  <collision>
    <origin xyz="0.080518 0.02156 -0.066" rpy="0 0 0"/>
    <geometry>
      <mesh filename="package://cloud_robot/urdf/meshes/Left_Rear_Wheel_1.stl" scale="0.001 0.001 0.001"/>
    </geometry>
  </collision>
</link>

<link name="Right_Rear_Wheel_1">
  <inertial>
    <origin xyz="9.514703854976436e-06 -0.03327999999999996 2.7755575615628914e-17" rpy="0 0 0"/>
    <mass value="3.8165954525863817"/>
    <inertia ixx="0.003628" iyy="0.004437" izz="0.003628" ixy="-0.0" iyz="-0.0" ixz="-0.0"/>
  </inertial>
  <visual>
    <origin xyz="0.080518 0.076826 -0.066" rpy="0 0 0"/>
    <geometry>
      <mesh filename="package://cloud_robot/urdf/meshes/Right_Rear_Wheel_1.stl" scale="0.001 0.001 0.001"/>
    </geometry>
    <material name="silver"/>
  </visual>
  <collision>
    <origin xyz="0.080518 0.076826 -0.066" rpy="0 0 0"/>
    <geometry>
      <mesh filename="package://cloud_robot/urdf/meshes/Right_Rear_Wheel_1.stl" scale="0.001 0.001 0.001"/>
    </geometry>
  </collision>
</link>

<link name="Left_Front_Fliper_1">
  <inertial>
    <origin xyz="0.0427356266996195 0.01335 -1.3877787807814457e-17" rpy="0 0 0"/>
    <mass value="3.12464418597158"/>
    <inertia ixx="0.002035" iyy="0.009493" izz="0.007829" ixy="0.0" iyz="0.0" ixz="-0.0"/>
  </inertial>
  <visual>
    <origin xyz="-0.080518 -0.05 -0.066" rpy="0 0 0"/>
    <geometry>
      <mesh filename="package://cloud_robot/urdf/meshes/Left_Front_Fliper_1.stl" scale="0.001 0.001 0.001"/>
    </geometry>
    <material name="silver"/>
  </visual>
  <collision>
    <origin xyz="-0.080518 -0.05 -0.066" rpy="0 0 0"/>
    <geometry>
      <mesh filename="package://cloud_robot/urdf/meshes/Left_Front_Fliper_1.stl" scale="0.001 0.001 0.001"/>
    </geometry>
  </collision>
</link>

<link name="Right_Front_Fliper_1">
  <inertial>
    <origin xyz="0.04273562669961954 -0.013349999999999945 0.0" rpy="0 0 0"/>
    <mass value="3.12464418597158"/>
    <inertia ixx="0.002035" iyy="0.009493" izz="0.007829" ixy="-0.0" iyz="-0.0" ixz="0.0"/>
  </inertial>
  <visual>
    <origin xyz="-0.080518 0.148386 -0.066" rpy="0 0 0"/>
    <geometry>
      <mesh filename="package://cloud_robot/urdf/meshes/Right_Front_Fliper_1.stl" scale="0.001 0.001 0.001"/>
    </geometry>
    <material name="silver"/>
  </visual>
  <collision>
    <origin xyz="-0.080518 0.148386 -0.066" rpy="0 0 0"/>
    <geometry>
      <mesh filename="package://cloud_robot/urdf/meshes/Right_Front_Fliper_1.stl" scale="0.001 0.001 0.001"/>
    </geometry>
  </collision>
</link>

<link name="Right_Rear_Fliper_1">
  <inertial>
    <origin xyz="-0.04273562669961954 -0.013349999999999945 0.0" rpy="0 0 0"/>
    <mass value="3.1246441859715794"/>
    <inertia ixx="0.002035" iyy="0.009493" izz="0.007829" ixy="0.0" iyz="-0.0" ixz="0.0"/>
  </inertial>
  <visual>
    <origin xyz="0.080518 0.148386 -0.066" rpy="0 0 0"/>
    <geometry>
      <mesh filename="package://cloud_robot/urdf/meshes/Right_Rear_Fliper_1.stl" scale="0.001 0.001 0.001"/>
    </geometry>
    <material name="silver"/>
  </visual>
  <collision>
    <origin xyz="0.080518 0.148386 -0.066" rpy="0 0 0"/>
    <geometry>
      <mesh filename="package://cloud_robot/urdf/meshes/Right_Rear_Fliper_1.stl" scale="0.001 0.001 0.001"/>
    </geometry>
  </collision>
</link>

<link name="Left_Rear_Fliper_1">
  <inertial>
    <origin xyz="-0.04273562669961961 0.01335 -1.3877787807814457e-17" rpy="0 0 0"/>
    <mass value="3.12464418597158"/>
    <inertia ixx="0.002035" iyy="0.009493" izz="0.007829" ixy="-0.0" iyz="0.0" ixz="0.0"/>
  </inertial>
  <visual>
    <origin xyz="0.080518 -0.05 -0.066" rpy="0 0 0"/>
    <geometry>
      <mesh filename="package://cloud_robot/urdf/meshes/Left_Rear_Fliper_1.stl" scale="0.001 0.001 0.001"/>
    </geometry>
    <material name="silver"/>
  </visual>
  <collision>
    <origin xyz="0.080518 -0.05 -0.066" rpy="0 0 0"/>
    <geometry>
      <mesh filename="package://cloud_robot/urdf/meshes/Left_Rear_Fliper_1.stl" scale="0.001 0.001 0.001"/>
    </geometry>
  </collision>
</link>

<link name="Joint_1_1">
  <inertial>
    <origin xyz="-0.006593053508868241 0.0 0.022539808161214633" rpy="0 0 0"/>
    <mass value="1.0976175500874272"/>
    <inertia ixx="0.000407" iyy="0.000564" izz="0.000615" ixy="-0.0" iyz="-0.0" ixz="5.2e-05"/>
  </inertial>
  <visual>
    <origin xyz="-0.071976 0.05 -0.11" rpy="0 0 0"/>
    <geometry>
      <mesh filename="package://cloud_robot/urdf/meshes/Joint_1_1.stl" scale="0.001 0.001 0.001"/>
    </geometry>
    <material name="silver"/>
  </visual>
  <collision>
    <origin xyz="-0.071976 0.05 -0.11" rpy="0 0 0"/>
    <geometry>
      <mesh filename="package://cloud_robot/urdf/meshes/Joint_1_1.stl" scale="0.001 0.001 0.001"/>
    </geometry>
  </collision>
</link>

<link name="Joint_Bridge_1_1">
  <inertial>
    <origin xyz="-0.05249999999988092 -0.0035000000000000447 -6.900036098045348e-14" rpy="0 0 0"/>
    <mass value="0.210202311444116"/>
    <inertia ixx="1.6e-05" iyy="0.000305" izz="0.000291" ixy="-0.0" iyz="-0.0" ixz="-0.0"/>
  </inertial>
  <visual>
    <origin xyz="-0.071976 0.074 -0.1397" rpy="0 0 0"/>
    <geometry>
      <mesh filename="package://cloud_robot/urdf/meshes/Joint_Bridge_1_1.stl" scale="0.001 0.001 0.001"/>
    </geometry>
    <material name="silver"/>
  </visual>
  <collision>
    <origin xyz="-0.071976 0.074 -0.1397" rpy="0 0 0"/>
    <geometry>
      <mesh filename="package://cloud_robot/urdf/meshes/Joint_Bridge_1_1.stl" scale="0.001 0.001 0.001"/>
    </geometry>
  </collision>
</link>

<link name="Joint_Bridge_2_1">
  <inertial>
    <origin xyz="-0.052499999999880906 0.0034999999999999996 -6.900036098045348e-14" rpy="0 0 0"/>
    <mass value="0.21020231144411708"/>
    <inertia ixx="1.6e-05" iyy="0.000305" izz="0.000291" ixy="-0.0" iyz="-0.0" ixz="-0.0"/>
  </inertial>
  <visual>
    <origin xyz="-0.071976 0.026 -0.1397" rpy="0 0 0"/>
    <geometry>
      <mesh filename="package://cloud_robot/urdf/meshes/Joint_Bridge_2_1.stl" scale="0.001 0.001 0.001"/>
    </geometry>
    <material name="silver"/>
  </visual>
  <collision>
    <origin xyz="-0.071976 0.026 -0.1397" rpy="0 0 0"/>
    <geometry>
      <mesh filename="package://cloud_robot/urdf/meshes/Joint_Bridge_2_1.stl" scale="0.001 0.001 0.001"/>
    </geometry>
  </collision>
</link>

<link name="Joint_2_1">
  <inertial>
    <origin xyz="0.002188552095745186 -0.026936196874102866 0.019710006862428964" rpy="0 0 0"/>
    <mass value="1.485619849727809"/>
    <inertia ixx="0.001134" iyy="0.001197" izz="0.000861" ixy="-4.9e-05" iyz="0.000108" ixz="0.000208"/>
  </inertial>
  <visual>
    <origin xyz="0.033024 0.026 -0.1397" rpy="0 0 0"/>
    <geometry>
      <mesh filename="package://cloud_robot/urdf/meshes/Joint_2_1.stl" scale="0.001 0.001 0.001"/>
    </geometry>
    <material name="silver"/>
  </visual>
  <collision>
    <origin xyz="0.033024 0.026 -0.1397" rpy="0 0 0"/>
    <geometry>
      <mesh filename="package://cloud_robot/urdf/meshes/Joint_2_1.stl" scale="0.001 0.001 0.001"/>
    </geometry>
  </collision>
</link>

<link name="Joint_3_1">
  <inertial>
    <origin xyz="0.03958059925091924 -0.0018254040488058856 0.0015011932395808947" rpy="0 0 0"/>
    <mass value="0.4960244910392703"/>
    <inertia ixx="8.6e-05" iyy="0.000262" izz="0.000314" ixy="-7e-06" iyz="-0.0" ixz="0.0"/>
  </inertial>
  <visual>
    <origin xyz="0.011524 0.05 -0.182601" rpy="0 0 0"/>
    <geometry>
      <mesh filename="package://cloud_robot/urdf/meshes/Joint_3_1.stl" scale="0.001 0.001 0.001"/>
    </geometry>
    <material name="silver"/>
  </visual>
  <collision>
    <origin xyz="0.011524 0.05 -0.182601" rpy="0 0 0"/>
    <geometry>
      <mesh filename="package://cloud_robot/urdf/meshes/Joint_3_1.stl" scale="0.001 0.001 0.001"/>
    </geometry>
  </collision>
</link>

<link name="Joint_4_1">
  <inertial>
    <origin xyz="0.05000371523751193 -0.027489382051494465 0.005784664192359679" rpy="0 0 0"/>
    <mass value="1.4697917423427727"/>
    <inertia ixx="0.0012" iyy="0.001045" izz="0.001279" ixy="-6.8e-05" iyz="0.000232" ixz="8.6e-05"/>
  </inertial>
  <visual>
    <origin xyz="-0.044325 0.026 -0.184101" rpy="0 0 0"/>
    <geometry>
      <mesh filename="package://cloud_robot/urdf/meshes/Joint_4_1.stl" scale="0.001 0.001 0.001"/>
    </geometry>
    <material name="silver"/>
  </visual>
  <collision>
    <origin xyz="-0.044325 0.026 -0.184101" rpy="0 0 0"/>
    <geometry>
      <mesh filename="package://cloud_robot/urdf/meshes/Joint_4_1.stl" scale="0.001 0.001 0.001"/>
    </geometry>
  </collision>
</link>

<link name="Joint_5_1">
  <inertial>
    <origin xyz="0.020879748229569783 0.00010384952783171197 -0.0002501826103843696" rpy="0 0 0"/>
    <mass value="0.48661437832818993"/>
    <inertia ixx="0.000151" iyy="0.000155" izz="0.000152" ixy="-0.0" iyz="-1e-06" ixz="0.0"/>
  </inertial>
  <visual>
    <origin xyz="-0.126526 0.048913 -0.185271" rpy="0 0 0"/>
    <geometry>
      <mesh filename="package://cloud_robot/urdf/meshes/Joint_5_1.stl" scale="0.001 0.001 0.001"/>
    </geometry>
    <material name="silver"/>
  </visual>
  <collision>
    <origin xyz="-0.126526 0.048913 -0.185271" rpy="0 0 0"/>
    <geometry>
      <mesh filename="package://cloud_robot/urdf/meshes/Joint_5_1.stl" scale="0.001 0.001 0.001"/>
    </geometry>
  </collision>
</link>

<joint name="Revolucion_1" type="continuous">
  <origin xyz="0.080518 -0.02156 0.066" rpy="0 0 0"/>
  <parent link="base_link"/>
  <child link="Left_Front_Wheel_1"/>
  <axis xyz="0.0 1.0 0.0"/>
</joint>

<joint name="Revolucion_2" type="continuous">
  <origin xyz="0.080518 -0.076826 0.066" rpy="0 0 0"/>
  <parent link="base_link"/>
  <child link="Right_Front_Wheel_1"/>
  <axis xyz="0.0 -1.0 0.0"/>
</joint>

<joint name="Revolucion_3" type="continuous">
  <origin xyz="-0.080518 -0.02156 0.066" rpy="0 0 0"/>
  <parent link="base_link"/>
  <child link="Left_Rear_Wheel_1"/>
  <axis xyz="0.0 1.0 0.0"/>
</joint>

<joint name="Revolucion_4" type="continuous">
  <origin xyz="-0.080518 -0.076826 0.066" rpy="0 0 0"/>
  <parent link="base_link"/>
  <child link="Right_Rear_Wheel_1"/>
  <axis xyz="0.0 -1.0 0.0"/>
</joint>

<joint name="Revolucion_5" type="continuous">
  <origin xyz="0.080518 0.05 0.066" rpy="0 0 0"/>
  <parent link="base_link"/>
  <child link="Left_Front_Fliper_1"/>
  <axis xyz="0.0 1.0 0.0"/>
</joint>

<joint name="Revolucion_6" type="continuous">
  <origin xyz="0.080518 -0.148386 0.066" rpy="0 0 0"/>
  <parent link="base_link"/>
  <child link="Right_Front_Fliper_1"/>
  <axis xyz="0.0 -1.0 0.0"/>
</joint>

<joint name="Revolucion_7" type="continuous">
  <origin xyz="-0.080518 -0.148386 0.066" rpy="0 0 0"/>
  <parent link="base_link"/>
  <child link="Right_Rear_Fliper_1"/>
  <axis xyz="0.0 -1.0 0.0"/>
</joint>

<joint name="Revolucion_8" type="continuous">
  <origin xyz="-0.080518 0.05 0.066" rpy="0 0 0"/>
  <parent link="base_link"/>
  <child link="Left_Rear_Fliper_1"/>
  <axis xyz="0.0 1.0 0.0"/>
</joint>

<joint name="Revolucion_9" type="continuous">
  <origin xyz="0.071976 -0.05 0.11" rpy="0 0 0"/>
  <parent link="base_link"/>
  <child link="Joint_1_1"/>
  <axis xyz="0.0 -0.0 -1.0"/>
</joint>

<joint name="Revolucion_10" type="continuous">
  <origin xyz="0.0 -0.024 0.0297" rpy="0 0 0"/>
  <parent link="Joint_1_1"/>
  <child link="Joint_Bridge_1_1"/>
  <axis xyz="0.0 1.0 -0.0"/>
</joint>

<joint name="Revolucion_11" type="continuous">
  <origin xyz="0.0 0.024 0.0297" rpy="0 0 0"/>
  <parent link="Joint_1_1"/>
  <child link="Joint_Bridge_2_1"/>
  <axis xyz="0.0 -1.0 0.0"/>
</joint>

<joint name="Revolucion_12" type="continuous">
  <origin xyz="-0.105 0.0 0.0" rpy="0 0 0"/>
  <parent link="Joint_Bridge_2_1"/>
  <child link="Joint_2_1"/>
  <axis xyz="0.0 1.0 -0.0"/>
</joint>

<joint name="Revolucion_13" type="continuous">
  <origin xyz="0.0215 -0.024 0.042901" rpy="0 0 0"/>
  <parent link="Joint_2_1"/>
  <child link="Joint_3_1"/>
  <axis xyz="-1.0 0.0 0.0"/>
</joint>

<joint name="Revolucion_14" type="continuous">
  <origin xyz="0.055849 0.024 0.0015" rpy="0 0 0"/>
  <parent link="Joint_3_1"/>
  <child link="Joint_4_1"/>
  <axis xyz="0.0 -1.0 0.0"/>
</joint>

<joint name="Revolucion_15" type="continuous">
  <origin xyz="0.082201 -0.022913 0.00117" rpy="0 0 0"/>
  <parent link="Joint_4_1"/>
  <child link="Joint_5_1"/>
  <axis xyz="-1.0 0.0 0.0"/>
</joint>

</robot>
